<?xml version="1.0" encoding="utf-8"?>
<!-- This URDF was automatically created by SolidWorks to URDF Exporter! Originally created by Stephen Brawner (brawner@gmail.com) 
     Commit Version: 1.6.0-4-g7f85cfe  Build Version: 1.6.7995.38578
     For more information, please see http://wiki.ros.org/sw_urdf_exporter -->

<robot
  name="Line1101">
  <link
    name="link1">
    <inertial>
      <origin
        xyz="0 0 0.015"
        rpy="0 0 0" />
      <mass
        value="0.0094248" />
      <inertia
        ixx="9.4248E-07"
        ixy="0"
        ixz="-2.732E-39"
        iyy="9.4248E-07"
        iyz="-4.5918E-39"
        izz="4.7124E-07" />
    </inertial>
    <visual>
      <origin
        xyz="0 0 0"
        rpy="0 0 0" />
      <geometry>
        <mesh
          filename="package://Line1101/meshes/link1.STL" />
      </geometry>
      <material
        name="link1">
        <color
          rgba="1 1 1 1" />
      </material>
    </visual>
    <collision>
      <origin
        xyz="0 0 0"
        rpy="0 0 0" />
      <geometry>
        <mesh
          filename="package://Line1101/meshes/link1.STL" />
      </geometry>
    </collision>
  </link>
<!--=====================link2 and link3====================-->
<!--=====================link2====================-->
  <joint
    name="fack_joint2"
    type="revolute">
    <origin
      xyz="0 0 0.03"
      rpy="0 0 0" />
    <parent
      link="link1" />
    <child
      link="fack_link2" />
    <axis
      xyz="1 0 0" />
    <limit
      lower="-0.785"
      upper="0.785"
      effort="0"
      velocity="0" />
  </joint>

  <link
    name="fack_link2">
    <visual>
      <origin
        xyz="0 0 0"
        rpy="0 0 0" />
      <geometry>
        <mesh
          filename="package://Line1101/meshes/link2.STL" />
      </geometry>
      <material
        name="fack_link2">
        <color
          rgba="0 1 1 0" />
      </material>
    </visual>
  </link>

  <joint
    name="joint2"
    type="revolute">
    <origin
      xyz="0 0 0"
      rpy="0 0 0" />
    <parent
      link="fack_link2" />
    <child
      link="link2" />
    <axis
      xyz="0 1 0" />
    <limit
      lower="-0.785"
      upper="0.785"
      effort="0"
      velocity="0" />
  </joint>

  <link
    name="link2">
    <inertial>
      <origin
        xyz="0 0 0.015"
        rpy="0 0 0" />
      <mass
        value="0.0094248" />
      <inertia
        ixx="9.4248E-07"
        ixy="0"
        ixz="-2.732E-39"
        iyy="9.4248E-07"
        iyz="-4.5918E-39"
        izz="4.7124E-07" />
    </inertial>
    <visual>
      <origin
        xyz="0 0 0"
        rpy="0 0 0" />
      <geometry>
        <mesh
          filename="package://Line1101/meshes/link2.STL" />
      </geometry>
      <material
        name="link2">
        <color
          rgba="0 1 1 1" />
      </material>
    </visual>
    <collision>
      <origin
        xyz="0 0 0"
        rpy="0 0 0" />
      <geometry>
        <mesh
          filename="package://Line1101/meshes/link2.STL" />
      </geometry>
    </collision>
  </link>
<!--=====================link3====================-->
  <joint
    name="fack_joint3"
    type="revolute">
    <origin
      xyz="0 0 0.03"
      rpy="0 0 0" />
    <parent
      link="link2" />
    <child
      link="fack_link3" />
    <axis
      xyz="1 0 0" />
    <limit
      lower="-0.785"
      upper="0.785"
      effort="0"
      velocity="0" />
  </joint>

  <link
    name="fack_link3">
    <visual>
      <origin
        xyz="0 0 0"
        rpy="0 0 0" />
      <geometry>
        <mesh
          filename="package://Line1101/meshes/link2.STL" />
      </geometry>
      <material
        name="fack_link3">
        <color
          rgba="0 1 1 0" />
      </material>
    </visual>
  </link>

  <joint
    name="joint3"
    type="revolute">
    <origin
      xyz="0 0 0"
      rpy="0 0 0" />
    <parent
      link="fack_link3" />
    <child
      link="link3" />
    <axis
      xyz="0 1 0" />
    <limit
      lower="-0.785"
      upper="0.785"
      effort="0"
      velocity="0" />
  </joint>

  <link
    name="link3">
    <inertial>
      <origin
        xyz="0 0 0.015"
        rpy="0 0 0" />
      <mass
        value="0.0094248" />
      <inertia
        ixx="9.4248E-07"
        ixy="0"
        ixz="-2.732E-39"
        iyy="9.4248E-07"
        iyz="-4.5918E-39"
        izz="4.7124E-07" />
    </inertial>
    <visual>
      <origin
        xyz="0 0 0"
        rpy="0 0 0" />
      <geometry>
        <mesh
          filename="package://Line1101/meshes/link2.STL" />
      </geometry>
      <material
        name="link3">
        <color
          rgba="1 1 1 1" />
      </material>
    </visual>
    <collision>
      <origin
        xyz="0 0 0"
        rpy="0 0 0" />
      <geometry>
        <mesh
          filename="package://Line1101/meshes/link2.STL" />
      </geometry>
    </collision>
  </link>
<!--=====================link4 and link5====================-->
<!--=====================link4====================-->
  <joint
    name="fack_joint4"
    type="revolute">
    <origin
      xyz="0 0 0.03"
      rpy="0 0 0" />
    <parent
      link="link3" />
    <child
      link="fack_link4" />
    <axis
      xyz="1 0 0" />
    <limit
      lower="-0.785"
      upper="0.785"
      effort="0"
      velocity="0" />
  </joint>

  <link
    name="fack_link4">
    <visual>
      <origin
        xyz="0 0 0"
        rpy="0 0 0" />
      <geometry>
        <mesh
          filename="package://Line1101/meshes/link2.STL" />
      </geometry>
      <material
        name="fack_link4">
        <color
          rgba="0 1 1 0" />
      </material>
    </visual>
  </link>

  <joint
    name="joint4"
    type="revolute">
    <origin
      xyz="0 0 0"
      rpy="0 0 0" />
    <parent
      link="fack_link4" />
    <child
      link="link4" />
    <axis
      xyz="0 1 0" />
    <limit
      lower="-0.785"
      upper="0.785"
      effort="0"
      velocity="0" />
  </joint>

  <link
    name="link4">
    <inertial>
      <origin
        xyz="0 0 0.015"
        rpy="0 0 0" />
      <mass
        value="0.0094248" />
      <inertia
        ixx="9.4248E-07"
        ixy="0"
        ixz="-2.732E-39"
        iyy="9.4248E-07"
        iyz="-4.5918E-39"
        izz="4.7124E-07" />
    </inertial>
    <visual>
      <origin
        xyz="0 0 0"
        rpy="0 0 0" />
      <geometry>
        <mesh
          filename="package://Line1101/meshes/link2.STL" />
      </geometry>
      <material
        name="link4">
        <color
          rgba="0 1 1 1" />
      </material>
    </visual>
    <collision>
      <origin
        xyz="0 0 0"
        rpy="0 0 0" />
      <geometry>
        <mesh
          filename="package://Line1101/meshes/link2.STL" />
      </geometry>
    </collision>
  </link>
<!--=====================link5====================-->
  <joint
    name="fack_joint5"
    type="revolute">
    <origin
      xyz="0 0 0.03"
      rpy="0 0 0" />
    <parent
      link="link4" />
    <child
      link="fack_link5" />
    <axis
      xyz="1 0 0" />
    <limit
      lower="-0.785"
      upper="0.785"
      effort="0"
      velocity="0" />
  </joint>

  <link
    name="fack_link5">
    <visual>
      <origin
        xyz="0 0 0"
        rpy="0 0 0" />
      <geometry>
        <mesh
          filename="package://Line1101/meshes/link2.STL" />
      </geometry>
      <material
        name="fack_link5">
        <color
          rgba="0 1 1 0" />
      </material>
    </visual>
  </link>

  <joint
    name="joint5"
    type="revolute">
    <origin
      xyz="0 0 0"
      rpy="0 0 0" />
    <parent
      link="fack_link5" />
    <child
      link="link5" />
    <axis
      xyz="0 1 0" />
    <limit
      lower="-0.785"
      upper="0.785"
      effort="0"
      velocity="0" />
  </joint>

  <link
    name="link5">
    <inertial>
      <origin
        xyz="0 0 0.015"
        rpy="0 0 0" />
      <mass
        value="0.0094248" />
      <inertia
        ixx="9.4248E-07"
        ixy="0"
        ixz="-2.732E-39"
        iyy="9.4248E-07"
        iyz="-4.5918E-39"
        izz="4.7124E-07" />
    </inertial>
    <visual>
      <origin
        xyz="0 0 0"
        rpy="0 0 0" />
      <geometry>
        <mesh
          filename="package://Line1101/meshes/link2.STL" />
      </geometry>
      <material
        name="link5">
        <color
          rgba="1 1 1 1" />
      </material>
    </visual>
    <collision>
      <origin
        xyz="0 0 0"
        rpy="0 0 0" />
      <geometry>
        <mesh
          filename="package://Line1101/meshes/link2.STL" />
      </geometry>
    </collision>
  </link>
<!--=====================link6 and link7====================-->
<!--=====================link6====================-->
  <joint
    name="fack_joint6"
    type="revolute">
    <origin
      xyz="0 0 0.03"
      rpy="0 0 0" />
    <parent
      link="link5" />
    <child
      link="fack_link6" />
    <axis
      xyz="1 0 0" />
    <limit
      lower="-0.785"
      upper="0.785"
      effort="0"
      velocity="0" />
  </joint>

  <link
    name="fack_link6">
    <visual>
      <origin
        xyz="0 0 0"
        rpy="0 0 0" />
      <geometry>
        <mesh
          filename="package://Line1101/meshes/link2.STL" />
      </geometry>
      <material
        name="fack_link6">
        <color
          rgba="0 1 1 0" />
      </material>
    </visual>
  </link>

  <joint
    name="joint6"
    type="revolute">
    <origin
      xyz="0 0 0"
      rpy="0 0 0" />
    <parent
      link="fack_link6" />
    <child
      link="link6" />
    <axis
      xyz="0 1 0" />
    <limit
      lower="-0.785"
      upper="0.785"
      effort="0"
      velocity="0" />
  </joint>

  <link
    name="link6">
    <inertial>
      <origin
        xyz="0 0 0.015"
        rpy="0 0 0" />
      <mass
        value="0.0094248" />
      <inertia
        ixx="9.4248E-07"
        ixy="0"
        ixz="-2.732E-39"
        iyy="9.4248E-07"
        iyz="-4.5918E-39"
        izz="4.7124E-07" />
    </inertial>
    <visual>
      <origin
        xyz="0 0 0"
        rpy="0 0 0" />
      <geometry>
        <mesh
          filename="package://Line1101/meshes/link2.STL" />
      </geometry>
      <material
        name="link6">
        <color
          rgba="0 1 1 1" />
      </material>
    </visual>
    <collision>
      <origin
        xyz="0 0 0"
        rpy="0 0 0" />
      <geometry>
        <mesh
          filename="package://Line1101/meshes/link2.STL" />
      </geometry>
    </collision>
  </link>
<!--=====================link7====================-->
  <joint
    name="fack_joint7"
    type="revolute">
    <origin
      xyz="0 0 0.03"
      rpy="0 0 0" />
    <parent
      link="link6" />
    <child
      link="fack_link7" />
    <axis
      xyz="1 0 0" />
    <limit
      lower="-0.785"
      upper="0.785"
      effort="0"
      velocity="0" />
  </joint>

  <link
    name="fack_link7">
    <visual>
      <origin
        xyz="0 0 0"
        rpy="0 0 0" />
      <geometry>
        <mesh
          filename="package://Line1101/meshes/link2.STL" />
      </geometry>
      <material
        name="fack_link7">
        <color
          rgba="0 1 1 0" />
      </material>
    </visual>
  </link>

  <joint
    name="joint7"
    type="revolute">
    <origin
      xyz="0 0 0"
      rpy="0 0 0" />
    <parent
      link="fack_link7" />
    <child
      link="link7" />
    <axis
      xyz="0 1 0" />
    <limit
      lower="-0.785"
      upper="0.785"
      effort="0"
      velocity="0" />
  </joint>

  <link
    name="link7">
    <inertial>
      <origin
        xyz="0 0 0.015"
        rpy="0 0 0" />
      <mass
        value="0.0094248" />
      <inertia
        ixx="9.4248E-07"
        ixy="0"
        ixz="-2.732E-39"
        iyy="9.4248E-07"
        iyz="-4.5918E-39"
        izz="4.7124E-07" />
    </inertial>
    <visual>
      <origin
        xyz="0 0 0"
        rpy="0 0 0" />
      <geometry>
        <mesh
          filename="package://Line1101/meshes/link2.STL" />
      </geometry>
      <material
        name="link7">
        <color
          rgba="1 1 1 1" />
      </material>
    </visual>
    <collision>
      <origin
        xyz="0 0 0"
        rpy="0 0 0" />
      <geometry>
        <mesh
          filename="package://Line1101/meshes/link2.STL" />
      </geometry>
    </collision>
  </link>

<!--=====================link8 and link9====================-->
<!--=====================link8====================-->
  <joint
    name="fack_joint8"
    type="revolute">
    <origin
      xyz="0 0 0.03"
      rpy="0 0 0" />
    <parent
      link="link7" />
    <child
      link="fack_link8" />
    <axis
      xyz="1 0 0" />
    <limit
      lower="-0.785"
      upper="0.785"
      effort="0"
      velocity="0" />
  </joint>

  <link
    name="fack_link8">
    <visual>
      <origin
        xyz="0 0 0"
        rpy="0 0 0" />
      <geometry>
        <mesh
          filename="package://Line1101/meshes/link2.STL" />
      </geometry>
      <material
        name="fack_link8">
        <color
          rgba="0 1 1 0" />
      </material>
    </visual>
  </link>

  <joint
    name="joint8"
    type="revolute">
    <origin
      xyz="0 0 0"
      rpy="0 0 0" />
    <parent
      link="fack_link8" />
    <child
      link="link8" />
    <axis
      xyz="0 1 0" />
    <limit
      lower="-0.785"
      upper="0.785"
      effort="0"
      velocity="0" />
  </joint>

  <link
    name="link8">
    <inertial>
      <origin
        xyz="0 0 0.015"
        rpy="0 0 0" />
      <mass
        value="0.0094248" />
      <inertia
        ixx="9.4248E-07"
        ixy="0"
        ixz="-2.732E-39"
        iyy="9.4248E-07"
        iyz="-4.5918E-39"
        izz="4.7124E-07" />
    </inertial>
    <visual>
      <origin
        xyz="0 0 0"
        rpy="0 0 0" />
      <geometry>
        <mesh
          filename="package://Line1101/meshes/link2.STL" />
      </geometry>
      <material
        name="link8">
        <color
          rgba="0 1 1 1" />
      </material>
    </visual>
    <collision>
      <origin
        xyz="0 0 0"
        rpy="0 0 0" />
      <geometry>
        <mesh
          filename="package://Line1101/meshes/link2.STL" />
      </geometry>
    </collision>
  </link>
<!--=====================link9====================-->
  <joint
    name="fack_joint9"
    type="revolute">
    <origin
      xyz="0 0 0.03"
      rpy="0 0 0" />
    <parent
      link="link8" />
    <child
      link="fack_link9" />
    <axis
      xyz="1 0 0" />
    <limit
      lower="-0.785"
      upper="0.785"
      effort="0"
      velocity="0" />
  </joint>

  <link
    name="fack_link9">
    <visual>
      <origin
        xyz="0 0 0"
        rpy="0 0 0" />
      <geometry>
        <mesh
          filename="package://Line1101/meshes/link2.STL" />
      </geometry>
      <material
        name="fack_link9">
        <color
          rgba="0 1 1 0" />
      </material>
    </visual>
  </link>

  <joint
    name="joint9"
    type="revolute">
    <origin
      xyz="0 0 0"
      rpy="0 0 0" />
    <parent
      link="fack_link9" />
    <child
      link="link9" />
    <axis
      xyz="0 1 0" />
    <limit
      lower="-0.785"
      upper="0.785"
      effort="0"
      velocity="0" />
  </joint>

  <link
    name="link9">
    <inertial>
      <origin
        xyz="0 0 0.015"
        rpy="0 0 0" />
      <mass
        value="0.0094248" />
      <inertia
        ixx="9.4248E-07"
        ixy="0"
        ixz="-2.732E-39"
        iyy="9.4248E-07"
        iyz="-4.5918E-39"
        izz="4.7124E-07" />
    </inertial>
    <visual>
      <origin
        xyz="0 0 0"
        rpy="0 0 0" />
      <geometry>
        <mesh
          filename="package://Line1101/meshes/link2.STL" />
      </geometry>
      <material
        name="link9">
        <color
          rgba="1 1 1 1" />
      </material>
    </visual>
    <collision>
      <origin
        xyz="0 0 0"
        rpy="0 0 0" />
      <geometry>
        <mesh
          filename="package://Line1101/meshes/link2.STL" />
      </geometry>
    </collision>
  </link>
<!--=====================link10 and link11====================-->
<!--=====================link10====================-->
  <joint
    name="fack_joint10"
    type="revolute">
    <origin
      xyz="0 0 0.03"
      rpy="0 0 0" />
    <parent
      link="link9" />
    <child
      link="fack_link10" />
    <axis
      xyz="1 0 0" />
    <limit
      lower="-0.785"
      upper="0.785"
      effort="0"
      velocity="0" />
  </joint>

  <link
    name="fack_link10">
    <visual>
      <origin
        xyz="0 0 0"
        rpy="0 0 0" />
      <geometry>
        <mesh
          filename="package://Line1101/meshes/link2.STL" />
      </geometry>
      <material
        name="fack_link10">
        <color
          rgba="0 1 1 0" />
      </material>
    </visual>
  </link>

  <joint
    name="joint10"
    type="revolute">
    <origin
      xyz="0 0 0"
      rpy="0 0 0" />
    <parent
      link="fack_link10" />
    <child
      link="link10" />
    <axis
      xyz="0 1 0" />
    <limit
      lower="-0.785"
      upper="0.785"
      effort="0"
      velocity="0" />
  </joint>

  <link
    name="link10">
    <inertial>
      <origin
        xyz="0 0 0.015"
        rpy="0 0 0" />
      <mass
        value="0.0094248" />
      <inertia
        ixx="9.4248E-07"
        ixy="0"
        ixz="-2.732E-39"
        iyy="9.4248E-07"
        iyz="-4.5918E-39"
        izz="4.7124E-07" />
    </inertial>
    <visual>
      <origin
        xyz="0 0 0"
        rpy="0 0 0" />
      <geometry>
        <mesh
          filename="package://Line1101/meshes/link2.STL" />
      </geometry>
      <material
        name="link10">
        <color
          rgba="0 1 1 1" />
      </material>
    </visual>
    <collision>
      <origin
        xyz="0 0 0"
        rpy="0 0 0" />
      <geometry>
        <mesh
          filename="package://Line1101/meshes/link2.STL" />
      </geometry>
    </collision>
  </link>
<!--=====================link11====================-->
  <joint
    name="fack_joint1-1"
    type="revolute">
    <origin
      xyz="0 0 0.03"
      rpy="0 0 0" />
    <parent
      link="link10" />
    <child
      link="fack_link1-1" />
    <axis
      xyz="1 0 0" />
    <limit
      lower="-0.785"
      upper="0.785"
      effort="0"
      velocity="0" />
  </joint>

  <link
    name="fack_link1-1">
    <visual>
      <origin
        xyz="0 0 0"
        rpy="0 0 0" />
      <geometry>
        <mesh
          filename="package://Line1101/meshes/link2.STL" />
      </geometry>
      <material
        name="fack_link1-1">
        <color
          rgba="0 1 1 0" />
      </material>
    </visual>
  </link>

  <joint
    name="joint1-1"
    type="revolute">
    <origin
      xyz="0 0 0"
      rpy="0 0 0" />
    <parent
      link="fack_link1-1" />
    <child
      link="link1-1" />
    <axis
      xyz="0 1 0" />
    <limit
      lower="-0.785"
      upper="0.785"
      effort="0"
      velocity="0" />
  </joint>

  <link
    name="link1-1">
    <inertial>
      <origin
        xyz="0 0 0.015"
        rpy="0 0 0" />
      <mass
        value="0.0094248" />
      <inertia
        ixx="9.4248E-07"
        ixy="0"
        ixz="-2.732E-39"
        iyy="9.4248E-07"
        iyz="-4.5918E-39"
        izz="4.7124E-07" />
    </inertial>
    <visual>
      <origin
        xyz="0 0 0"
        rpy="0 0 0" />
      <geometry>
        <mesh
          filename="package://Line1101/meshes/link2.STL" />
      </geometry>
      <material
        name="link1-1">
        <color
          rgba="1 1 1 1" />
      </material>
    </visual>
    <collision>
      <origin
        xyz="0 0 0"
        rpy="0 0 0" />
      <geometry>
        <mesh
          filename="package://Line1101/meshes/link2.STL" />
      </geometry>
    </collision>
  </link>

<!--=====================link12 and link13====================-->
<!--=====================link12====================-->
  <joint
    name="fack_joint12"
    type="revolute">
    <origin
      xyz="0 0 0.03"
      rpy="0 0 0" />
    <parent
      link="link1-1" />
    <child
      link="fack_link12" />
    <axis
      xyz="1 0 0" />
    <limit
      lower="-0.785"
      upper="0.785"
      effort="0"
      velocity="0" />
  </joint>

  <link
    name="fack_link12">
    <visual>
      <origin
        xyz="0 0 0"
        rpy="0 0 0" />
      <geometry>
        <mesh
          filename="package://Line1101/meshes/link2.STL" />
      </geometry>
      <material
        name="fack_link12">
        <color
          rgba="0 1 1 0" />
      </material>
    </visual>
  </link>

  <joint
    name="joint12"
    type="revolute">
    <origin
      xyz="0 0 0"
      rpy="0 0 0" />
    <parent
      link="fack_link12" />
    <child
      link="link12" />
    <axis
      xyz="0 1 0" />
    <limit
      lower="-0.785"
      upper="0.785"
      effort="0"
      velocity="0" />
  </joint>

  <link
    name="link12">
    <inertial>
      <origin
        xyz="0 0 0.015"
        rpy="0 0 0" />
      <mass
        value="0.0094248" />
      <inertia
        ixx="9.4248E-07"
        ixy="0"
        ixz="-2.732E-39"
        iyy="9.4248E-07"
        iyz="-4.5918E-39"
        izz="4.7124E-07" />
    </inertial>
    <visual>
      <origin
        xyz="0 0 0"
        rpy="0 0 0" />
      <geometry>
        <mesh
          filename="package://Line1101/meshes/link2.STL" />
      </geometry>
      <material
        name="link12">
        <color
          rgba="0 1 1 1" />
      </material>
    </visual>
    <collision>
      <origin
        xyz="0 0 0"
        rpy="0 0 0" />
      <geometry>
        <mesh
          filename="package://Line1101/meshes/link2.STL" />
      </geometry>
    </collision>
  </link>
<!--=====================link13====================-->
  <joint
    name="fack_joint13"
    type="revolute">
    <origin
      xyz="0 0 0.03"
      rpy="0 0 0" />
    <parent
      link="link12" />
    <child
      link="fack_link13" />
    <axis
      xyz="1 0 0" />
    <limit
      lower="-0.785"
      upper="0.785"
      effort="0"
      velocity="0" />
  </joint>

  <link
    name="fack_link13">
    <visual>
      <origin
        xyz="0 0 0"
        rpy="0 0 0" />
      <geometry>
        <mesh
          filename="package://Line1101/meshes/link2.STL" />
      </geometry>
      <material
        name="fack_link13">
        <color
          rgba="0 1 1 0" />
      </material>
    </visual>
  </link>

  <joint
    name="joint13"
    type="revolute">
    <origin
      xyz="0 0 0"
      rpy="0 0 0" />
    <parent
      link="fack_link13" />
    <child
      link="link13" />
    <axis
      xyz="0 1 0" />
    <limit
      lower="-0.785"
      upper="0.785"
      effort="0"
      velocity="0" />
  </joint>

  <link
    name="link13">
    <inertial>
      <origin
        xyz="0 0 0.015"
        rpy="0 0 0" />
      <mass
        value="0.0094248" />
      <inertia
        ixx="9.4248E-07"
        ixy="0"
        ixz="-2.732E-39"
        iyy="9.4248E-07"
        iyz="-4.5918E-39"
        izz="4.7124E-07" />
    </inertial>
    <visual>
      <origin
        xyz="0 0 0"
        rpy="0 0 0" />
      <geometry>
        <mesh
          filename="package://Line1101/meshes/link2.STL" />
      </geometry>
      <material
        name="link13">
        <color
          rgba="1 1 1 1" />
      </material>
    </visual>
    <collision>
      <origin
        xyz="0 0 0"
        rpy="0 0 0" />
      <geometry>
        <mesh
          filename="package://Line1101/meshes/link2.STL" />
      </geometry>
    </collision>
  </link>

<!--=====================link14 and link15====================-->
<!--=====================link14====================-->
  <joint
    name="fack_joint14"
    type="revolute">
    <origin
      xyz="0 0 0.03"
      rpy="0 0 0" />
    <parent
      link="link13" />
    <child
      link="fack_link14" />
    <axis
      xyz="1 0 0" />
    <limit
      lower="-0.785"
      upper="0.785"
      effort="0"
      velocity="0" />
  </joint>

  <link
    name="fack_link14">
    <visual>
      <origin
        xyz="0 0 0"
        rpy="0 0 0" />
      <geometry>
        <mesh
          filename="package://Line1101/meshes/link2.STL" />
      </geometry>
      <material
        name="fack_link14">
        <color
          rgba="0 1 1 0" />
      </material>
    </visual>
  </link>

  <joint
    name="joint14"
    type="revolute">
    <origin
      xyz="0 0 0"
      rpy="0 0 0" />
    <parent
      link="fack_link14" />
    <child
      link="link14" />
    <axis
      xyz="0 1 0" />
    <limit
      lower="-0.785"
      upper="0.785"
      effort="0"
      velocity="0" />
  </joint>

  <link
    name="link14">
    <inertial>
      <origin
        xyz="0 0 0.015"
        rpy="0 0 0" />
      <mass
        value="0.0094248" />
      <inertia
        ixx="9.4248E-07"
        ixy="0"
        ixz="-2.732E-39"
        iyy="9.4248E-07"
        iyz="-4.5918E-39"
        izz="4.7124E-07" />
    </inertial>
    <visual>
      <origin
        xyz="0 0 0"
        rpy="0 0 0" />
      <geometry>
        <mesh
          filename="package://Line1101/meshes/link2.STL" />
      </geometry>
      <material
        name="link14">
        <color
          rgba="0 1 1 1" />
      </material>
    </visual>
    <collision>
      <origin
        xyz="0 0 0"
        rpy="0 0 0" />
      <geometry>
        <mesh
          filename="package://Line1101/meshes/link2.STL" />
      </geometry>
    </collision>
  </link>
<!--=====================link15====================-->
  <joint
    name="fack_joint15"
    type="revolute">
    <origin
      xyz="0 0 0.03"
      rpy="0 0 0" />
    <parent
      link="link14" />
    <child
      link="fack_link15" />
    <axis
      xyz="1 0 0" />
    <limit
      lower="-0.785"
      upper="0.785"
      effort="0"
      velocity="0" />
  </joint>

  <link
    name="fack_link15">
    <visual>
      <origin
        xyz="0 0 0"
        rpy="0 0 0" />
      <geometry>
        <mesh
          filename="package://Line1101/meshes/link2.STL" />
      </geometry>
      <material
        name="fack_link15">
        <color
          rgba="0 1 1 0" />
      </material>
    </visual>
  </link>

  <joint
    name="joint15"
    type="revolute">
    <origin
      xyz="0 0 0"
      rpy="0 0 0" />
    <parent
      link="fack_link15" />
    <child
      link="link15" />
    <axis
      xyz="0 1 0" />
    <limit
      lower="-0.785"
      upper="0.785"
      effort="0"
      velocity="0" />
  </joint>

  <link
    name="link15">
    <inertial>
      <origin
        xyz="0 0 0.015"
        rpy="0 0 0" />
      <mass
        value="0.0094248" />
      <inertia
        ixx="9.4248E-07"
        ixy="0"
        ixz="-2.732E-39"
        iyy="9.4248E-07"
        iyz="-4.5918E-39"
        izz="4.7124E-07" />
    </inertial>
    <visual>
      <origin
        xyz="0 0 0"
        rpy="0 0 0" />
      <geometry>
        <mesh
          filename="package://Line1101/meshes/link2.STL" />
      </geometry>
      <material
        name="link15">
        <color
          rgba="1 1 1 1" />
      </material>
    </visual>
    <collision>
      <origin
        xyz="0 0 0"
        rpy="0 0 0" />
      <geometry>
        <mesh
          filename="package://Line1101/meshes/link2.STL" />
      </geometry>
    </collision>
  </link>

<!--=====================link16 and link17====================-->
<!--=====================link16====================-->
  <joint
    name="fack_joint16"
    type="revolute">
    <origin
      xyz="0 0 0.03"
      rpy="0 0 0" />
    <parent
      link="link15" />
    <child
      link="fack_link16" />
    <axis
      xyz="1 0 0" />
    <limit
      lower="-0.785"
      upper="0.785"
      effort="0"
      velocity="0" />
  </joint>

  <link
    name="fack_link16">
    <visual>
      <origin
        xyz="0 0 0"
        rpy="0 0 0" />
      <geometry>
        <mesh
          filename="package://Line1101/meshes/link2.STL" />
      </geometry>
      <material
        name="fack_link16">
        <color
          rgba="0 1 1 0" />
      </material>
    </visual>
  </link>

  <joint
    name="joint16"
    type="revolute">
    <origin
      xyz="0 0 0"
      rpy="0 0 0" />
    <parent
      link="fack_link16" />
    <child
      link="link16" />
    <axis
      xyz="0 1 0" />
    <limit
      lower="-0.785"
      upper="0.785"
      effort="0"
      velocity="0" />
  </joint>

  <link
    name="link16">
    <inertial>
      <origin
        xyz="0 0 0.015"
        rpy="0 0 0" />
      <mass
        value="0.0094248" />
      <inertia
        ixx="9.4248E-07"
        ixy="0"
        ixz="-2.732E-39"
        iyy="9.4248E-07"
        iyz="-4.5918E-39"
        izz="4.7124E-07" />
    </inertial>
    <visual>
      <origin
        xyz="0 0 0"
        rpy="0 0 0" />
      <geometry>
        <mesh
          filename="package://Line1101/meshes/link2.STL" />
      </geometry>
      <material
        name="link16">
        <color
          rgba="0 1 1 1" />
      </material>
    </visual>
    <collision>
      <origin
        xyz="0 0 0"
        rpy="0 0 0" />
      <geometry>
        <mesh
          filename="package://Line1101/meshes/link2.STL" />
      </geometry>
    </collision>
  </link>
<!--=====================link17====================-->
  <joint
    name="fack_joint17"
    type="revolute">
    <origin
      xyz="0 0 0.03"
      rpy="0 0 0" />
    <parent
      link="link16" />
    <child
      link="fack_link17" />
    <axis
      xyz="1 0 0" />
    <limit
      lower="-0.785"
      upper="0.785"
      effort="0"
      velocity="0" />
  </joint>

  <link
    name="fack_link17">
    <visual>
      <origin
        xyz="0 0 0"
        rpy="0 0 0" />
      <geometry>
        <mesh
          filename="package://Line1101/meshes/link2.STL" />
      </geometry>
      <material
        name="fack_link17">
        <color
          rgba="0 1 1 0" />
      </material>
    </visual>
  </link>

  <joint
    name="joint17"
    type="revolute">
    <origin
      xyz="0 0 0"
      rpy="0 0 0" />
    <parent
      link="fack_link17" />
    <child
      link="link17" />
    <axis
      xyz="0 1 0" />
    <limit
      lower="-0.785"
      upper="0.785"
      effort="0"
      velocity="0" />
  </joint>

  <link
    name="link17">
    <inertial>
      <origin
        xyz="0 0 0.015"
        rpy="0 0 0" />
      <mass
        value="0.0094248" />
      <inertia
        ixx="9.4248E-07"
        ixy="0"
        ixz="-2.732E-39"
        iyy="9.4248E-07"
        iyz="-4.5918E-39"
        izz="4.7124E-07" />
    </inertial>
    <visual>
      <origin
        xyz="0 0 0"
        rpy="0 0 0" />
      <geometry>
        <mesh
          filename="package://Line1101/meshes/link2.STL" />
      </geometry>
      <material
        name="link17">
        <color
          rgba="1 1 1 1" />
      </material>
    </visual>
    <collision>
      <origin
        xyz="0 0 0"
        rpy="0 0 0" />
      <geometry>
        <mesh
          filename="package://Line1101/meshes/link2.STL" />
      </geometry>
    </collision>
  </link>

<!--=====================link18 and link19====================-->
<!--=====================link18====================-->
  <joint
    name="fack_joint18"
    type="revolute">
    <origin
      xyz="0 0 0.03"
      rpy="0 0 0" />
    <parent
      link="link17" />
    <child
      link="fack_link18" />
    <axis
      xyz="1 0 0" />
    <limit
      lower="-0.785"
      upper="0.785"
      effort="0"
      velocity="0" />
  </joint>

  <link
    name="fack_link18">
    <visual>
      <origin
        xyz="0 0 0"
        rpy="0 0 0" />
      <geometry>
        <mesh
          filename="package://Line1101/meshes/link2.STL" />
      </geometry>
      <material
        name="fack_link18">
        <color
          rgba="0 1 1 0" />
      </material>
    </visual>
  </link>

  <joint
    name="joint18"
    type="revolute">
    <origin
      xyz="0 0 0"
      rpy="0 0 0" />
    <parent
      link="fack_link18" />
    <child
      link="link18" />
    <axis
      xyz="0 1 0" />
    <limit
      lower="-0.785"
      upper="0.785"
      effort="0"
      velocity="0" />
  </joint>

  <link
    name="link18">
    <inertial>
      <origin
        xyz="0 0 0.015"
        rpy="0 0 0" />
      <mass
        value="0.0094248" />
      <inertia
        ixx="9.4248E-07"
        ixy="0"
        ixz="-2.732E-39"
        iyy="9.4248E-07"
        iyz="-4.5918E-39"
        izz="4.7124E-07" />
    </inertial>
    <visual>
      <origin
        xyz="0 0 0"
        rpy="0 0 0" />
      <geometry>
        <mesh
          filename="package://Line1101/meshes/link2.STL" />
      </geometry>
      <material
        name="link18">
        <color
          rgba="0 1 1 1" />
      </material>
    </visual>
    <collision>
      <origin
        xyz="0 0 0"
        rpy="0 0 0" />
      <geometry>
        <mesh
          filename="package://Line1101/meshes/link2.STL" />
      </geometry>
    </collision>
  </link>
<!--=====================link19====================-->
  <joint
    name="fack_joint19"
    type="revolute">
    <origin
      xyz="0 0 0.03"
      rpy="0 0 0" />
    <parent
      link="link18" />
    <child
      link="fack_link19" />
    <axis
      xyz="1 0 0" />
    <limit
      lower="-0.785"
      upper="0.785"
      effort="0"
      velocity="0" />
  </joint>

  <link
    name="fack_link19">
    <visual>
      <origin
        xyz="0 0 0"
        rpy="0 0 0" />
      <geometry>
        <mesh
          filename="package://Line1101/meshes/link2.STL" />
      </geometry>
      <material
        name="fack_link19">
        <color
          rgba="0 1 1 0" />
      </material>
    </visual>
  </link>

  <joint
    name="joint19"
    type="revolute">
    <origin
      xyz="0 0 0"
      rpy="0 0 0" />
    <parent
      link="fack_link19" />
    <child
      link="link19" />
    <axis
      xyz="0 1 0" />
    <limit
      lower="-0.785"
      upper="0.785"
      effort="0"
      velocity="0" />
  </joint>

  <link
    name="link19">
    <inertial>
      <origin
        xyz="0 0 0.015"
        rpy="0 0 0" />
      <mass
        value="0.0094248" />
      <inertia
        ixx="9.4248E-07"
        ixy="0"
        ixz="-2.732E-39"
        iyy="9.4248E-07"
        iyz="-4.5918E-39"
        izz="4.7124E-07" />
    </inertial>
    <visual>
      <origin
        xyz="0 0 0"
        rpy="0 0 0" />
      <geometry>
        <mesh
          filename="package://Line1101/meshes/link2.STL" />
      </geometry>
      <material
        name="link19">
        <color
          rgba="1 1 1 1" />
      </material>
    </visual>
    <collision>
      <origin
        xyz="0 0 0"
        rpy="0 0 0" />
      <geometry>
        <mesh
          filename="package://Line1101/meshes/link2.STL" />
      </geometry>
    </collision>
  </link>
</robot>